 Network jojodev_default  Creating
 Network jojodev_default  Created
 Container jojodev-db-1  Creating
 Container jojodev-db-1  Created
 Container jojodev-api02-1  Creating
 Container jojodev-api01-1  Creating
 Container jojodev-api02-1  Created
 Container jojodev-api01-1  Created
 Container jojodev-nginx-1  Creating
 Container jojodev-nginx-1  Created
Attaching to api01-1, api02-1, db-1, nginx-1
db-1     | The files belonging to this database system will be owned by user "postgres".
db-1     | This user must also own the server process.
db-1     | 
db-1     | The database cluster will be initialized with locale "en_US.utf8".
db-1     | The default database encoding has accordingly been set to "UTF8".
db-1     | The default text search configuration will be set to "english".
db-1     | 
db-1     | Data page checksums are disabled.
db-1     | 
db-1     | fixing permissions on existing directory /var/lib/postgresql/data ... ok
db-1     | creating subdirectories ... ok
db-1     | selecting default max_connections ... 100
db-1     | selecting default shared_buffers ... 128MB
db-1     | selecting dynamic shared memory implementation ... posix
db-1     | creating configuration files ... ok
db-1     | running bootstrap script ... ok
db-1     | performing post-bootstrap initialization ... ok
db-1     | 
db-1     | WARNING: enabling "trust" authentication for local connections
db-1     | You can change this by editing pg_hba.conf or using the option -A, or
db-1     | --auth-local and --auth-host, the next time you run initdb.
db-1     | syncing data to disk ... ok
db-1     | 
db-1     | Success. You can now start the database server using:
db-1     | 
db-1     |     pg_ctl -D /var/lib/postgresql/data -l logfile start
db-1     | 
db-1     | waiting for server to start....2024-02-16 10:06:18.022 UTC [39] LOG:  listening on IPv4 address "127.0.0.1", port 5432
db-1     | 2024-02-16 10:06:18.022 UTC [39] LOG:  could not bind IPv6 address "::1": Cannot assign requested address
db-1     | 2024-02-16 10:06:18.022 UTC [39] HINT:  Is another postmaster already running on port 5432? If not, wait a few seconds and retry.
db-1     | 2024-02-16 10:06:18.028 UTC [39] LOG:  listening on Unix socket "/var/run/postgresql/.s.PGSQL.5432"
db-1     | 2024-02-16 10:06:18.043 UTC [40] LOG:  database system was shut down at 2024-02-16 10:06:16 UTC
db-1     | 2024-02-16 10:06:18.116 UTC [39] LOG:  database system is ready to accept connections
db-1     |  done
db-1     | server started
db-1     | CREATE DATABASE
db-1     | 
db-1     | CREATE ROLE
db-1     | 
db-1     | 
db-1     | /usr/local/bin/docker-entrypoint.sh: running /docker-entrypoint-initdb.d/init.sql
db-1     | CREATE TABLE
db-1     | CREATE TABLE
db-1     | CREATE TABLE
db-1     | DO
db-1     | 
db-1     | 
db-1     | waiting for server to shut down...2024-02-16 10:06:19.557 UTC [39] LOG:  received fast shutdown request
db-1     | .2024-02-16 10:06:19.617 UTC [39] LOG:  aborting any active transactions
db-1     | 2024-02-16 10:06:19.714 UTC [39] LOG:  worker process: logical replication launcher (PID 46) exited with exit code 1
db-1     | 2024-02-16 10:06:19.715 UTC [41] LOG:  shutting down
db-1     | 2024-02-16 10:06:19.841 UTC [39] LOG:  database system is shut down
db-1     |  done
db-1     | server stopped
db-1     | 
db-1     | PostgreSQL init process complete; ready for start up.
db-1     | 
db-1     | 2024-02-16 10:06:19.869 UTC [1] LOG:  listening on IPv4 address "0.0.0.0", port 5432
db-1     | 2024-02-16 10:06:19.869 UTC [1] LOG:  listening on IPv6 address "::", port 5432
db-1     | 2024-02-16 10:06:19.876 UTC [1] LOG:  listening on Unix socket "/var/run/postgresql/.s.PGSQL.5432"
db-1     | 2024-02-16 10:06:19.919 UTC [75] LOG:  database system was shut down at 2024-02-16 10:06:19 UTC
db-1     | 2024-02-16 10:06:19.927 UTC [1] LOG:  database system is ready to accept connections
nginx-1  | /docker-entrypoint.sh: /docker-entrypoint.d/ is not empty, will attempt to perform configuration
nginx-1  | /docker-entrypoint.sh: Looking for shell scripts in /docker-entrypoint.d/
nginx-1  | /docker-entrypoint.sh: Launching /docker-entrypoint.d/10-listen-on-ipv6-by-default.sh
nginx-1  | 10-listen-on-ipv6-by-default.sh: info: Getting the checksum of /etc/nginx/conf.d/default.conf
nginx-1  | 10-listen-on-ipv6-by-default.sh: info: Enabled listen on IPv6 in /etc/nginx/conf.d/default.conf
nginx-1  | /docker-entrypoint.sh: Sourcing /docker-entrypoint.d/15-local-resolvers.envsh
nginx-1  | /docker-entrypoint.sh: Launching /docker-entrypoint.d/20-envsubst-on-templates.sh
nginx-1  | /docker-entrypoint.sh: Launching /docker-entrypoint.d/30-tune-worker-processes.sh
nginx-1  | /docker-entrypoint.sh: Configuration complete; ready for start up
api01-1  |  * Serving Flask app 'main'
api01-1  |  * Debug mode: off
api01-1  | [31m[1mWARNING: This is a development server. Do not use it in a production deployment. Use a production WSGI server instead.[0m
api01-1  |  * Running on all addresses (0.0.0.0)
api01-1  |  * Running on http://127.0.0.1:5000
api01-1  |  * Running on http://192.168.224.4:5000
api01-1  | [33mPress CTRL+C to quit[0m
api02-1  |  * Serving Flask app 'main'
api02-1  |  * Debug mode: off
api02-1  | [31m[1mWARNING: This is a development server. Do not use it in a production deployment. Use a production WSGI server instead.[0m
api02-1  |  * Running on all addresses (0.0.0.0)
api02-1  |  * Running on http://127.0.0.1:5000
api02-1  |  * Running on http://192.168.224.3:5000
api02-1  | [33mPress CTRL+C to quit[0m
api01-1  | 192.168.224.5 - - [16/Feb/2024 10:06:23] "GET /clientes/1/extrato HTTP/1.0" 200 -
api02-1  | 192.168.224.5 - - [16/Feb/2024 10:06:23] "GET /clientes/1/extrato HTTP/1.0" 200 -
api01-1  | /app/database.py:18: SAWarning: Usage of the 'Session.add()' operation is not currently supported within the execution stage of the flush process. Results may not be consistent.  Consider using alternative event listeners or connection-level operations instead.
api01-1  |   s.add(objeto)
api01-1  | [2024-02-16 10:06:28,500] ERROR in app: Exception on /clientes/1/transacoes [POST]
api01-1  | Traceback (most recent call last):
api01-1  |   File "/app/database.py", line 19, in save_objeto
api01-1  |     s.commit()
api01-1  |   File "/usr/local/lib/python3.9/site-packages/sqlalchemy/orm/session.py", line 1969, in commit
api01-1  |     trans.commit(_to_root=True)
api01-1  |   File "<string>", line 2, in commit
api01-1  |   File "/usr/local/lib/python3.9/site-packages/sqlalchemy/orm/state_changes.py", line 139, in _go
api01-1  |     ret_value = fn(self, *arg, **kw)
api01-1  |   File "/usr/local/lib/python3.9/site-packages/sqlalchemy/orm/session.py", line 1274, in commit
api01-1  |     self._parent.commit(_to_root=True)
api01-1  |   File "<string>", line 2, in commit
api01-1  |   File "/usr/local/lib/python3.9/site-packages/sqlalchemy/orm/state_changes.py", line 121, in _go
api01-1  |     raise sa_exc.IllegalStateChangeError(
api01-1  | sqlalchemy.exc.IllegalStateChangeError: Method 'commit()' can't be called here; method '_prepare_impl()' is already in progress and this would cause an unexpected state change to <SessionTransactionState.CLOSED: 5> (Background on this error at: https://sqlalche.me/e/20/isce)
api01-1  | 
api01-1  | During handling of the above exception, another exception occurred:
api01-1  | 
api01-1  | Traceback (most recent call last):
api01-1  |   File "/usr/local/lib/python3.9/site-packages/flask/app.py", line 1463, in wsgi_app
api01-1  |     response = self.full_dispatch_request()
api01-1  |   File "/usr/local/lib/python3.9/site-packages/flask/app.py", line 872, in full_dispatch_request
api01-1  |     rv = self.handle_user_exception(e)
api01-1  |   File "/usr/local/lib/python3.9/site-packages/flask/app.py", line 870, in full_dispatch_request
api01-1  |     rv = self.dispatch_request()
api01-1  |   File "/usr/local/lib/python3.9/site-packages/flask/app.py", line 855, in dispatch_request
api01-1  |     return self.ensure_sync(self.view_functions[rule.endpoint])(**view_args)  # type: ignore[no-any-return]
api01-1  |   File "/app/main.py", line 42, in create_transacao
api01-1  |     save_objeto(nova_transacao, session)
api01-1  |   File "/app/database.py", line 21, in save_objeto
api01-1  |     s.rollback()
api01-1  |   File "/usr/local/lib/python3.9/site-packages/sqlalchemy/orm/session.py", line 1931, in rollback
api01-1  |     self._transaction.rollback(_to_root=True)
api01-1  |   File "<string>", line 2, in rollback
api01-1  |   File "/usr/local/lib/python3.9/site-packages/sqlalchemy/orm/state_changes.py", line 121, in _go
api01-1  |     raise sa_exc.IllegalStateChangeError(
api01-1  | sqlalchemy.exc.IllegalStateChangeError: Method 'rollback()' can't be called here; method '_prepare_impl()' is already in progress and this would cause an unexpected state change to <SessionTransactionState.CLOSED: 5> (Background on this error at: https://sqlalche.me/e/20/isce)
api01-1  | 192.168.224.5 - - [16/Feb/2024 10:06:28] "[35m[1mPOST /clientes/1/transacoes HTTP/1.0[0m" 500 -
api02-1  | [2024-02-16 10:06:28,503] ERROR in app: Exception on /clientes/1/transacoes [POST]
api02-1  | Traceback (most recent call last):
api02-1  |   File "/usr/local/lib/python3.9/site-packages/flask/app.py", line 1463, in wsgi_app
api02-1  |     response = self.full_dispatch_request()
api02-1  |   File "/usr/local/lib/python3.9/site-packages/flask/app.py", line 872, in full_dispatch_request
api02-1  |     rv = self.handle_user_exception(e)
api02-1  |   File "/usr/local/lib/python3.9/site-packages/flask/app.py", line 870, in full_dispatch_request
api02-1  |     rv = self.dispatch_request()
api02-1  |   File "/usr/local/lib/python3.9/site-packages/flask/app.py", line 855, in dispatch_request
api02-1  |     return self.ensure_sync(self.view_functions[rule.endpoint])(**view_args)  # type: ignore[no-any-return]
api02-1  |   File "/app/main.py", line 20, in create_transacao
api02-1  |     cliente = get_cliente_by_id(cliente_id)
api02-1  |   File "/app/main.py", line 15, in get_cliente_by_id
api02-1  |     cliente = session.query(Cliente).filter_by(id=cliente_id).first()
api02-1  |   File "/usr/local/lib/python3.9/site-packages/sqlalchemy/orm/query.py", line 2748, in first
api02-1  |     return self.limit(1)._iter().first()  # type: ignore
api02-1  |   File "/usr/local/lib/python3.9/site-packages/sqlalchemy/orm/query.py", line 2847, in _iter
api02-1  |     result: Union[ScalarResult[_T], Result[_T]] = self.session.execute(
api02-1  |   File "/usr/local/lib/python3.9/site-packages/sqlalchemy/orm/session.py", line 2308, in execute
api02-1  |     return self._execute_internal(
api02-1  |   File "/usr/local/lib/python3.9/site-packages/sqlalchemy/orm/session.py", line 2180, in _execute_internal
api02-1  |     conn = self._connection_for_bind(bind)
api02-1  |   File "/usr/local/lib/python3.9/site-packages/sqlalchemy/orm/session.py", line 2047, in _connection_for_bind
api02-1  |     return trans._connection_for_bind(engine, execution_options)
api02-1  |   File "<string>", line 2, in _connection_for_bind
api02-1  |   File "/usr/local/lib/python3.9/site-packages/sqlalchemy/orm/state_changes.py", line 103, in _go
api02-1  |     self._raise_for_prerequisite_state(fn.__name__, current_state)
api02-1  |   File "/usr/local/lib/python3.9/site-packages/sqlalchemy/orm/session.py", line 952, in _raise_for_prerequisite_state
api02-1  |     raise sa_exc.InvalidRequestError(
api02-1  | sqlalchemy.exc.InvalidRequestError: This session is in 'prepared' state; no further SQL can be emitted within this transaction.
api02-1  | 192.168.224.5 - - [16/Feb/2024 10:06:28] "[35m[1mPOST /clientes/1/transacoes HTTP/1.0[0m" 500 -
api01-1  | [2024-02-16 10:06:28,513] ERROR in app: Exception on /clientes/1/transacoes [POST]
api01-1  | Traceback (most recent call last):
api01-1  |   File "/app/database.py", line 19, in save_objeto
api01-1  |     s.commit()
api01-1  |   File "/usr/local/lib/python3.9/site-packages/sqlalchemy/orm/session.py", line 1969, in commit
api01-1  |     trans.commit(_to_root=True)
api01-1  |   File "<string>", line 2, in commit
api01-1  |   File "/usr/local/lib/python3.9/site-packages/sqlalchemy/orm/state_changes.py", line 139, in _go
api01-1  |     ret_value = fn(self, *arg, **kw)
api01-1  |   File "/usr/local/lib/python3.9/site-packages/sqlalchemy/orm/session.py", line 1274, in commit
api01-1  |     self._parent.commit(_to_root=True)
api01-1  |   File "<string>", line 2, in commit
api01-1  |   File "/usr/local/lib/python3.9/site-packages/sqlalchemy/orm/state_changes.py", line 121, in _go
api01-1  |     raise sa_exc.IllegalStateChangeError(
api01-1  | sqlalchemy.exc.IllegalStateChangeError: Method 'commit()' can't be called here; method 'rollback()' is already in progress and this would cause an unexpected state change to <SessionTransactionState.CLOSED: 5> (Background on this error at: https://sqlalche.me/e/20/isce)
api01-1  | 
api01-1  | During handling of the above exception, another exception occurred:
api01-1  | 
api01-1  | Traceback (most recent call last):
api01-1  |   File "/usr/local/lib/python3.9/site-packages/flask/app.py", line 1463, in wsgi_app
api01-1  |     response = self.full_dispatch_request()
api01-1  |   File "/usr/local/lib/python3.9/site-packages/flask/app.py", line 872, in full_dispatch_request
api01-1  |     rv = self.handle_user_exception(e)
api01-1  |   File "/usr/local/lib/python3.9/site-packages/flask/app.py", line 870, in full_dispatch_request
api01-1  |     rv = self.dispatch_request()
api01-1  |   File "/usr/local/lib/python3.9/site-packages/flask/app.py", line 855, in dispatch_request
api01-1  |     return self.ensure_sync(self.view_functions[rule.endpoint])(**view_args)  # type: ignore[no-any-return]
api01-1  |   File "/app/main.py", line 42, in create_transacao
api01-1  |     save_objeto(nova_transacao, session)
api01-1  |   File "/app/database.py", line 21, in save_objeto
api01-1  |     s.rollback()
api01-1  |   File "/usr/local/lib/python3.9/site-packages/sqlalchemy/orm/session.py", line 1931, in rollback
api01-1  |     self._transaction.rollback(_to_root=True)
api01-1  |   File "<string>", line 2, in rollback
api01-1  |   File "/usr/local/lib/python3.9/site-packages/sqlalchemy/orm/state_changes.py", line 121, in _go
api01-1  |     raise sa_exc.IllegalStateChangeError(
api01-1  | sqlalchemy.exc.IllegalStateChangeError: Method 'rollback()' can't be called here; method 'rollback()' is already in progress and this would cause an unexpected state change to <SessionTransactionState.CLOSED: 5> (Background on this error at: https://sqlalche.me/e/20/isce)
api01-1  | 192.168.224.5 - - [16/Feb/2024 10:06:28] "[35m[1mPOST /clientes/1/transacoes HTTP/1.0[0m" 500 -
api02-1  | 192.168.224.5 - - [16/Feb/2024 10:06:28] "POST /clientes/1/transacoes HTTP/1.0" 200 -
api02-1  | 192.168.224.5 - - [16/Feb/2024 10:06:28] "POST /clientes/1/transacoes HTTP/1.0" 200 -
api01-1  | [2024-02-16 10:06:28,516] ERROR in app: Exception on /clientes/1/transacoes [POST]
api01-1  | Traceback (most recent call last):
api01-1  |   File "/usr/local/lib/python3.9/site-packages/sqlalchemy/orm/session.py", line 4408, in _flush
api01-1  |     flush_context.execute()
api01-1  |   File "/usr/local/lib/python3.9/site-packages/sqlalchemy/orm/unitofwork.py", line 466, in execute
api01-1  |     rec.execute(self)
api01-1  |   File "/usr/local/lib/python3.9/site-packages/sqlalchemy/orm/unitofwork.py", line 679, in execute
api01-1  |     util.preloaded.orm_persistence.delete_obj(
api01-1  |   File "/usr/local/lib/python3.9/site-packages/sqlalchemy/orm/persistence.py", line 174, in delete_obj
api01-1  |     states_to_delete = list(
api01-1  |   File "/usr/local/lib/python3.9/site-packages/sqlalchemy/orm/persistence.py", line 309, in _organize_states_for_delete
api01-1  |     for state, dict_, mapper, connection in _connections_for_states(
api01-1  |   File "/usr/local/lib/python3.9/site-packages/sqlalchemy/orm/persistence.py", line 1736, in _connections_for_states
api01-1  |     connection = uowtransaction.transaction.connection(base_mapper)
api01-1  |   File "<string>", line 2, in connection
api01-1  |   File "/usr/local/lib/python3.9/site-packages/sqlalchemy/orm/state_changes.py", line 103, in _go
api01-1  |     self._raise_for_prerequisite_state(fn.__name__, current_state)
api01-1  |   File "/usr/local/lib/python3.9/site-packages/sqlalchemy/orm/session.py", line 944, in _raise_for_prerequisite_state
api01-1  |     raise sa_exc.ResourceClosedError("This transaction is closed")
api01-1  | sqlalchemy.exc.ResourceClosedError: This transaction is closed
api01-1  | 
api01-1  | During handling of the above exception, another exception occurred:
api01-1  | 
api01-1  | Traceback (most recent call last):
api01-1  |   File "/usr/local/lib/python3.9/site-packages/flask/app.py", line 1463, in wsgi_app
api01-1  |     response = self.full_dispatch_request()
api01-1  |   File "/usr/local/lib/python3.9/site-packages/flask/app.py", line 872, in full_dispatch_request
api01-1  |     rv = self.handle_user_exception(e)
api01-1  |   File "/usr/local/lib/python3.9/site-packages/flask/app.py", line 870, in full_dispatch_request
api01-1  |     rv = self.dispatch_request()
api01-1  |   File "/usr/local/lib/python3.9/site-packages/flask/app.py", line 855, in dispatch_request
api01-1  |     return self.ensure_sync(self.view_functions[rule.endpoint])(**view_args)  # type: ignore[no-any-return]
api01-1  |   File "/app/main.py", line 29, in create_transacao
api01-1  |     saldo = get_saldo_by_cliente_id(cliente.id)
api01-1  |   File "/app/main.py", line 11, in get_saldo_by_cliente_id
api01-1  |     saldo = session.query(Saldo).filter_by(cliente_id = cliente_id_buscado).first()
api01-1  |   File "/usr/local/lib/python3.9/site-packages/sqlalchemy/orm/query.py", line 2748, in first
api01-1  |     return self.limit(1)._iter().first()  # type: ignore
api01-1  |   File "/usr/local/lib/python3.9/site-packages/sqlalchemy/orm/query.py", line 2847, in _iter
api01-1  |     result: Union[ScalarResult[_T], Result[_T]] = self.session.execute(
api01-1  |   File "/usr/local/lib/python3.9/site-packages/sqlalchemy/orm/session.py", line 2308, in execute
api01-1  |     return self._execute_internal(
api01-1  |   File "/usr/local/lib/python3.9/site-packages/sqlalchemy/orm/session.py", line 2169, in _execute_internal
api01-1  |     ) = compile_state_cls.orm_pre_session_exec(
api01-1  |   File "/usr/local/lib/python3.9/site-packages/sqlalchemy/orm/context.py", line 551, in orm_pre_session_exec
api01-1  |     session._autoflush()
api01-1  |   File "/usr/local/lib/python3.9/site-packages/sqlalchemy/orm/session.py", line 3010, in _autoflush
api01-1  |     self.flush()
api01-1  |   File "/usr/local/lib/python3.9/site-packages/sqlalchemy/orm/session.py", line 4312, in flush
api01-1  |     self._flush(objects)
api01-1  |   File "/usr/local/lib/python3.9/site-packages/sqlalchemy/orm/session.py", line 4448, in _flush
api01-1  |     transaction.rollback(_capture_exception=True)
api01-1  |   File "/usr/local/lib/python3.9/site-packages/sqlalchemy/util/langhelpers.py", line 150, in __exit__
api01-1  |     raise value.with_traceback(traceback)
api01-1  |   File "/usr/local/lib/python3.9/site-packages/sqlalchemy/orm/session.py", line 4448, in _flush
api01-1  |     transaction.rollback(_capture_exception=True)
api01-1  |   File "<string>", line 2, in rollback
api01-1  |   File "/usr/local/lib/python3.9/site-packages/sqlalchemy/orm/state_changes.py", line 103, in _go
api01-1  |     self._raise_for_prerequisite_state(fn.__name__, current_state)
api01-1  |   File "/usr/local/lib/python3.9/site-packages/sqlalchemy/orm/session.py", line 944, in _raise_for_prerequisite_state
api01-1  |     raise sa_exc.ResourceClosedError("This transaction is closed")
api01-1  | sqlalchemy.exc.ResourceClosedError: This transaction is closed
api01-1  | 192.168.224.5 - - [16/Feb/2024 10:06:28] "[35m[1mPOST /clientes/1/transacoes HTTP/1.0[0m" 500 -
api01-1  | [2024-02-16 10:06:28,516] ERROR in app: Exception on /clientes/1/transacoes [POST]
api01-1  | Traceback (most recent call last):
api01-1  |   File "/usr/local/lib/python3.9/site-packages/sqlalchemy/orm/session.py", line 4408, in _flush
api01-1  |     flush_context.execute()
api01-1  |   File "/usr/local/lib/python3.9/site-packages/sqlalchemy/orm/unitofwork.py", line 466, in execute
api01-1  |     rec.execute(self)
api01-1  |   File "/usr/local/lib/python3.9/site-packages/sqlalchemy/orm/unitofwork.py", line 642, in execute
api01-1  |     util.preloaded.orm_persistence.save_obj(
api01-1  |   File "/usr/local/lib/python3.9/site-packages/sqlalchemy/orm/persistence.py", line 60, in save_obj
api01-1  |     for (
api01-1  |   File "/usr/local/lib/python3.9/site-packages/sqlalchemy/orm/persistence.py", line 221, in _organize_states_for_save
api01-1  |     for state, dict_, mapper, connection in _connections_for_states(
api01-1  |   File "/usr/local/lib/python3.9/site-packages/sqlalchemy/orm/persistence.py", line 1736, in _connections_for_states
api01-1  |     connection = uowtransaction.transaction.connection(base_mapper)
api01-1  |   File "<string>", line 2, in connection
api01-1  |   File "/usr/local/lib/python3.9/site-packages/sqlalchemy/orm/state_changes.py", line 103, in _go
api01-1  |     self._raise_for_prerequisite_state(fn.__name__, current_state)
api01-1  |   File "/usr/local/lib/python3.9/site-packages/sqlalchemy/orm/session.py", line 944, in _raise_for_prerequisite_state
api01-1  |     raise sa_exc.ResourceClosedError("This transaction is closed")
api01-1  | sqlalchemy.exc.ResourceClosedError: This transaction is closed
api01-1  | 
api01-1  | During handling of the above exception, another exception occurred:
api01-1  | 
api01-1  | Traceback (most recent call last):
api01-1  |   File "/usr/local/lib/python3.9/site-packages/flask/app.py", line 1463, in wsgi_app
api01-1  |     response = self.full_dispatch_request()
api01-1  |   File "/usr/local/lib/python3.9/site-packages/flask/app.py", line 872, in full_dispatch_request
api01-1  |     rv = self.handle_user_exception(e)
api01-1  |   File "/usr/local/lib/python3.9/site-packages/flask/app.py", line 870, in full_dispatch_request
api01-1  |     rv = self.dispatch_request()
api01-1  |   File "/usr/local/lib/python3.9/site-packages/flask/app.py", line 855, in dispatch_request
api01-1  |     return self.ensure_sync(self.view_functions[rule.endpoint])(**view_args)  # type: ignore[no-any-return]
api01-1  |   File "/app/main.py", line 42, in create_transacao
api01-1  |     save_objeto(nova_transacao, session)
api01-1  |   File "/app/database.py", line 22, in save_objeto
api01-1  |     raise e
api01-1  |   File "/app/database.py", line 19, in save_objeto
api01-1  |     s.commit()
api01-1  |   File "/usr/local/lib/python3.9/site-packages/sqlalchemy/orm/session.py", line 1969, in commit
api01-1  |     trans.commit(_to_root=True)
api01-1  |   File "<string>", line 2, in commit
api01-1  |   File "/usr/local/lib/python3.9/site-packages/sqlalchemy/orm/state_changes.py", line 139, in _go
api01-1  |     ret_value = fn(self, *arg, **kw)
api01-1  |   File "/usr/local/lib/python3.9/site-packages/sqlalchemy/orm/session.py", line 1256, in commit
api01-1  |     self._prepare_impl()
api01-1  |   File "<string>", line 2, in _prepare_impl
api01-1  |   File "/usr/local/lib/python3.9/site-packages/sqlalchemy/orm/state_changes.py", line 139, in _go
api01-1  |     ret_value = fn(self, *arg, **kw)
api01-1  |   File "/usr/local/lib/python3.9/site-packages/sqlalchemy/orm/session.py", line 1231, in _prepare_impl
api01-1  |     self.session.flush()
api01-1  |   File "/usr/local/lib/python3.9/site-packages/sqlalchemy/orm/session.py", line 4312, in flush
api01-1  |     self._flush(objects)
api01-1  |   File "/usr/local/lib/python3.9/site-packages/sqlalchemy/orm/session.py", line 4448, in _flush
api01-1  |     transaction.rollback(_capture_exception=True)
api01-1  |   File "/usr/local/lib/python3.9/site-packages/sqlalchemy/util/langhelpers.py", line 150, in __exit__
api01-1  |     raise value.with_traceback(traceback)
api01-1  |   File "/usr/local/lib/python3.9/site-packages/sqlalchemy/orm/session.py", line 4448, in _flush
api01-1  |     transaction.rollback(_capture_exception=True)
api01-1  |   File "<string>", line 2, in rollback
api01-1  |   File "/usr/local/lib/python3.9/site-packages/sqlalchemy/orm/state_changes.py", line 103, in _go
api01-1  |     self._raise_for_prerequisite_state(fn.__name__, current_state)
api01-1  |   File "/usr/local/lib/python3.9/site-packages/sqlalchemy/orm/session.py", line 944, in _raise_for_prerequisite_state
api01-1  |     raise sa_exc.ResourceClosedError("This transaction is closed")
api01-1  | sqlalchemy.exc.ResourceClosedError: This transaction is closed
api01-1  | 192.168.224.5 - - [16/Feb/2024 10:06:28] "[35m[1mPOST /clientes/1/transacoes HTTP/1.0[0m" 500 -
api01-1  | 192.168.224.5 - - [16/Feb/2024 10:06:28] "POST /clientes/1/transacoes HTTP/1.0" 200 -
api02-1  | /app/database.py:18: SAWarning: Usage of the 'Session.add()' operation is not currently supported within the execution stage of the flush process. Results may not be consistent.  Consider using alternative event listeners or connection-level operations instead.
api02-1  |   s.add(objeto)
api02-1  | [2024-02-16 10:06:28,533] ERROR in app: Exception on /clientes/1/transacoes [POST]
api02-1  | Traceback (most recent call last):
api02-1  |   File "/app/database.py", line 19, in save_objeto
api02-1  |     s.commit()
api02-1  |   File "/usr/local/lib/python3.9/site-packages/sqlalchemy/orm/session.py", line 1969, in commit
api02-1  |     trans.commit(_to_root=True)
api02-1  |   File "<string>", line 2, in commit
api02-1  |   File "/usr/local/lib/python3.9/site-packages/sqlalchemy/orm/state_changes.py", line 139, in _go
api02-1  |     ret_value = fn(self, *arg, **kw)
api02-1  |   File "/usr/local/lib/python3.9/site-packages/sqlalchemy/orm/session.py", line 1274, in commit
api02-1  |     self._parent.commit(_to_root=True)
api02-1  |   File "<string>", line 2, in commit
api02-1  |   File "/usr/local/lib/python3.9/site-packages/sqlalchemy/orm/state_changes.py", line 121, in _go
api02-1  |     raise sa_exc.IllegalStateChangeError(
api02-1  | sqlalchemy.exc.IllegalStateChangeError: Method 'commit()' can't be called here; method '_prepare_impl()' is already in progress and this would cause an unexpected state change to <SessionTransactionState.CLOSED: 5> (Background on this error at: https://sqlalche.me/e/20/isce)
api02-1  | 
api02-1  | During handling of the above exception, another exception occurred:
api02-1  | 
api02-1  | Traceback (most recent call last):
api02-1  |   File "/usr/local/lib/python3.9/site-packages/flask/app.py", line 1463, in wsgi_app
api02-1  |     response = self.full_dispatch_request()
api02-1  |   File "/usr/local/lib/python3.9/site-packages/flask/app.py", line 872, in full_dispatch_request
api02-1  |     rv = self.handle_user_exception(e)
api02-1  |   File "/usr/local/lib/python3.9/site-packages/flask/app.py", line 870, in full_dispatch_request
api02-1  |     rv = self.dispatch_request()
api02-1  |   File "/usr/local/lib/python3.9/site-packages/flask/app.py", line 855, in dispatch_request
api02-1  |     return self.ensure_sync(self.view_functions[rule.endpoint])(**view_args)  # type: ignore[no-any-return]
api02-1  |   File "/app/main.py", line 42, in create_transacao
api02-1  |     save_objeto(nova_transacao, session)
api02-1  |   File "/app/database.py", line 21, in save_objeto
api02-1  |     s.rollback()
api02-1  |   File "/usr/local/lib/python3.9/site-packages/sqlalchemy/orm/session.py", line 1931, in rollback
api02-1  |     self._transaction.rollback(_to_root=True)
api02-1  |   File "<string>", line 2, in rollback
api02-1  |   File "/usr/local/lib/python3.9/site-packages/sqlalchemy/orm/state_changes.py", line 121, in _go
api02-1  |     raise sa_exc.IllegalStateChangeError(
api02-1  | sqlalchemy.exc.IllegalStateChangeError: Method 'rollback()' can't be called here; method '_prepare_impl()' is already in progress and this would cause an unexpected state change to <SessionTransactionState.CLOSED: 5> (Background on this error at: https://sqlalche.me/e/20/isce)
api01-1  | 192.168.224.5 - - [16/Feb/2024 10:06:28] "POST /clientes/1/transacoes HTTP/1.0" 200 -
api01-1  | [2024-02-16 10:06:28,534] ERROR in app: Exception on /clientes/1/transacoes [POST]
api01-1  | Traceback (most recent call last):
api01-1  |   File "/usr/local/lib/python3.9/site-packages/flask/app.py", line 1463, in wsgi_app
api01-1  |     response = self.full_dispatch_request()
api01-1  |   File "/usr/local/lib/python3.9/site-packages/flask/app.py", line 872, in full_dispatch_request
api01-1  |     rv = self.handle_user_exception(e)
api01-1  |   File "/usr/local/lib/python3.9/site-packages/flask/app.py", line 870, in full_dispatch_request
api01-1  |     rv = self.dispatch_request()
api01-1  |   File "/usr/local/lib/python3.9/site-packages/flask/app.py", line 855, in dispatch_request
api01-1  |     return self.ensure_sync(self.view_functions[rule.endpoint])(**view_args)  # type: ignore[no-any-return]
api01-1  |   File "/app/main.py", line 20, in create_transacao
api01-1  |     cliente = get_cliente_by_id(cliente_id)
api01-1  |   File "/app/main.py", line 15, in get_cliente_by_id
api01-1  |     cliente = session.query(Cliente).filter_by(id=cliente_id).first()
api01-1  |   File "/usr/local/lib/python3.9/site-packages/sqlalchemy/orm/query.py", line 2748, in first
api01-1  |     return self.limit(1)._iter().first()  # type: ignore
api01-1  |   File "/usr/local/lib/python3.9/site-packages/sqlalchemy/orm/query.py", line 2847, in _iter
api01-1  |     result: Union[ScalarResult[_T], Result[_T]] = self.session.execute(
api01-1  |   File "/usr/local/lib/python3.9/site-packages/sqlalchemy/orm/session.py", line 2308, in execute
api01-1  |     return self._execute_internal(
api01-1  |   File "/usr/local/lib/python3.9/site-packages/sqlalchemy/orm/session.py", line 2180, in _execute_internal
api01-1  |     conn = self._connection_for_bind(bind)
api01-1  |   File "/usr/local/lib/python3.9/site-packages/sqlalchemy/orm/session.py", line 2047, in _connection_for_bind
api01-1  |     return trans._connection_for_bind(engine, execution_options)
api01-1  |   File "<string>", line 2, in _connection_for_bind
api01-1  |   File "/usr/local/lib/python3.9/site-packages/sqlalchemy/orm/state_changes.py", line 103, in _go
api01-1  |     self._raise_for_prerequisite_state(fn.__name__, current_state)
api01-1  |   File "/usr/local/lib/python3.9/site-packages/sqlalchemy/orm/session.py", line 952, in _raise_for_prerequisite_state
api01-1  |     raise sa_exc.InvalidRequestError(
api01-1  | sqlalchemy.exc.InvalidRequestError: This session is in 'prepared' state; no further SQL can be emitted within this transaction.
api01-1  | 192.168.224.5 - - [16/Feb/2024 10:06:28] "[35m[1mPOST /clientes/1/transacoes HTTP/1.0[0m" 500 -
api01-1  | [2024-02-16 10:06:28,536] ERROR in app: Exception on /clientes/1/transacoes [POST]
api01-1  | Traceback (most recent call last):
api01-1  |   File "/usr/local/lib/python3.9/site-packages/flask/app.py", line 1463, in wsgi_app
api01-1  |     response = self.full_dispatch_request()
api01-1  |   File "/usr/local/lib/python3.9/site-packages/flask/app.py", line 872, in full_dispatch_request
api01-1  |     rv = self.handle_user_exception(e)
api01-1  |   File "/usr/local/lib/python3.9/site-packages/flask/app.py", line 870, in full_dispatch_request
api01-1  |     rv = self.dispatch_request()
api01-1  |   File "/usr/local/lib/python3.9/site-packages/flask/app.py", line 855, in dispatch_request
api01-1  |     return self.ensure_sync(self.view_functions[rule.endpoint])(**view_args)  # type: ignore[no-any-return]
api01-1  |   File "/app/main.py", line 29, in create_transacao
api01-1  |     saldo = get_saldo_by_cliente_id(cliente.id)
api01-1  |   File "/app/main.py", line 11, in get_saldo_by_cliente_id
api01-1  |     saldo = session.query(Saldo).filter_by(cliente_id = cliente_id_buscado).first()
api01-1  |   File "/usr/local/lib/python3.9/site-packages/sqlalchemy/orm/query.py", line 2748, in first
api01-1  |     return self.limit(1)._iter().first()  # type: ignore
api01-1  |   File "/usr/local/lib/python3.9/site-packages/sqlalchemy/orm/query.py", line 2847, in _iter
api01-1  |     result: Union[ScalarResult[_T], Result[_T]] = self.session.execute(
api01-1  |   File "/usr/local/lib/python3.9/site-packages/sqlalchemy/orm/session.py", line 2308, in execute
api01-1  |     return self._execute_internal(
api01-1  |   File "/usr/local/lib/python3.9/site-packages/sqlalchemy/orm/session.py", line 2180, in _execute_internal
api01-1  |     conn = self._connection_for_bind(bind)
api01-1  |   File "/usr/local/lib/python3.9/site-packages/sqlalchemy/orm/session.py", line 2047, in _connection_for_bind
api01-1  |     return trans._connection_for_bind(engine, execution_options)
api01-1  |   File "<string>", line 2, in _connection_for_bind
api01-1  |   File "/usr/local/lib/python3.9/site-packages/sqlalchemy/orm/state_changes.py", line 103, in _go
api01-1  |     self._raise_for_prerequisite_state(fn.__name__, current_state)
api01-1  |   File "/usr/local/lib/python3.9/site-packages/sqlalchemy/orm/session.py", line 952, in _raise_for_prerequisite_state
api01-1  |     raise sa_exc.InvalidRequestError(
api01-1  | sqlalchemy.exc.InvalidRequestError: This session is in 'prepared' state; no further SQL can be emitted within this transaction.
api01-1  | 192.168.224.5 - - [16/Feb/2024 10:06:28] "[35m[1mPOST /clientes/1/transacoes HTTP/1.0[0m" 500 -
api02-1  | 192.168.224.5 - - [16/Feb/2024 10:06:28] "[35m[1mPOST /clientes/1/transacoes HTTP/1.0[0m" 500 -
api02-1  | [2024-02-16 10:06:28,536] ERROR in app: Exception on /clientes/1/transacoes [POST]
api02-1  | Traceback (most recent call last):
api02-1  |   File "/usr/local/lib/python3.9/site-packages/sqlalchemy/orm/session.py", line 4408, in _flush
api02-1  |     flush_context.execute()
api02-1  |   File "/usr/local/lib/python3.9/site-packages/sqlalchemy/orm/unitofwork.py", line 466, in execute
api02-1  |     rec.execute(self)
api02-1  |   File "/usr/local/lib/python3.9/site-packages/sqlalchemy/orm/unitofwork.py", line 642, in execute
api02-1  |     util.preloaded.orm_persistence.save_obj(
api02-1  |   File "/usr/local/lib/python3.9/site-packages/sqlalchemy/orm/persistence.py", line 60, in save_obj
api02-1  |     for (
api02-1  |   File "/usr/local/lib/python3.9/site-packages/sqlalchemy/orm/persistence.py", line 221, in _organize_states_for_save
api02-1  |     for state, dict_, mapper, connection in _connections_for_states(
api02-1  |   File "/usr/local/lib/python3.9/site-packages/sqlalchemy/orm/persistence.py", line 1736, in _connections_for_states
api02-1  |     connection = uowtransaction.transaction.connection(base_mapper)
api02-1  |   File "<string>", line 2, in connection
api02-1  |   File "/usr/local/lib/python3.9/site-packages/sqlalchemy/orm/state_changes.py", line 103, in _go
api02-1  |     self._raise_for_prerequisite_state(fn.__name__, current_state)
api02-1  |   File "/usr/local/lib/python3.9/site-packages/sqlalchemy/orm/session.py", line 944, in _raise_for_prerequisite_state
api02-1  |     raise sa_exc.ResourceClosedError("This transaction is closed")
api02-1  | sqlalchemy.exc.ResourceClosedError: This transaction is closed
api02-1  | 
api02-1  | During handling of the above exception, another exception occurred:
api02-1  | 
api02-1  | Traceback (most recent call last):
api02-1  |   File "/usr/local/lib/python3.9/site-packages/flask/app.py", line 1463, in wsgi_app
api02-1  |     response = self.full_dispatch_request()
api02-1  |   File "/usr/local/lib/python3.9/site-packages/flask/app.py", line 872, in full_dispatch_request
api02-1  |     rv = self.handle_user_exception(e)
api02-1  |   File "/usr/local/lib/python3.9/site-packages/flask/app.py", line 870, in full_dispatch_request
api02-1  |     rv = self.dispatch_request()
api02-1  |   File "/usr/local/lib/python3.9/site-packages/flask/app.py", line 855, in dispatch_request
api02-1  |     return self.ensure_sync(self.view_functions[rule.endpoint])(**view_args)  # type: ignore[no-any-return]
api02-1  |   File "/app/main.py", line 42, in create_transacao
api02-1  |     save_objeto(nova_transacao, session)
api02-1  |   File "/app/database.py", line 22, in save_objeto
api02-1  |     raise e
api02-1  |   File "/app/database.py", line 19, in save_objeto
api02-1  |     s.commit()
api02-1  |   File "/usr/local/lib/python3.9/site-packages/sqlalchemy/orm/session.py", line 1969, in commit
api02-1  |     trans.commit(_to_root=True)
api02-1  |   File "<string>", line 2, in commit
api02-1  |   File "/usr/local/lib/python3.9/site-packages/sqlalchemy/orm/state_changes.py", line 139, in _go
api02-1  |     ret_value = fn(self, *arg, **kw)
api02-1  |   File "/usr/local/lib/python3.9/site-packages/sqlalchemy/orm/session.py", line 1256, in commit
api02-1  |     self._prepare_impl()
api02-1  |   File "<string>", line 2, in _prepare_impl
api02-1  |   File "/usr/local/lib/python3.9/site-packages/sqlalchemy/orm/state_changes.py", line 139, in _go
api02-1  |     ret_value = fn(self, *arg, **kw)
api02-1  |   File "/usr/local/lib/python3.9/site-packages/sqlalchemy/orm/session.py", line 1231, in _prepare_impl
api02-1  |     self.session.flush()
api02-1  |   File "/usr/local/lib/python3.9/site-packages/sqlalchemy/orm/session.py", line 4312, in flush
api02-1  |     self._flush(objects)
api02-1  |   File "/usr/local/lib/python3.9/site-packages/sqlalchemy/orm/session.py", line 4448, in _flush
api02-1  |     transaction.rollback(_capture_exception=True)
api02-1  |   File "/usr/local/lib/python3.9/site-packages/sqlalchemy/util/langhelpers.py", line 150, in __exit__
api02-1  |     raise value.with_traceback(traceback)
api02-1  |   File "/usr/local/lib/python3.9/site-packages/sqlalchemy/orm/session.py", line 4448, in _flush
api02-1  |     transaction.rollback(_capture_exception=True)
api02-1  |   File "<string>", line 2, in rollback
